cpu-bind=MASK - mlgpu04, task  0  0 [1375]: mask 0xffff set
ConnectionRefusedError: [Errno 111] Connection refused

The above exception was the direct cause of the following exception:

Traceback (most recent call last):
  File "/home/sukthank/anaconda3/envs/fairnas/lib/python3.9/site-packages/distributed/comm/core.py", line 289, in connect
    comm = await asyncio.wait_for(
  File "/home/sukthank/anaconda3/envs/fairnas/lib/python3.9/asyncio/tasks.py", line 479, in wait_for
    return fut.result()
  File "/home/sukthank/anaconda3/envs/fairnas/lib/python3.9/site-packages/distributed/comm/tcp.py", line 451, in connect
    convert_stream_closed_error(self, e)
  File "/home/sukthank/anaconda3/envs/fairnas/lib/python3.9/site-packages/distributed/comm/tcp.py", line 148, in convert_stream_closed_error
    raise CommClosedError(f"in {obj}: {exc.__class__.__name__}: {exc}") from exc
distributed.comm.core.CommClosedError: in <distributed.comm.tcp.TCPConnector object at 0x7f5639747af0>: ConnectionRefusedError: [Errno 111] Connection refused

The above exception was the direct cause of the following exception:

Traceback (most recent call last):
  File "/work/dlclarge2/sukthank-ZCP_Competition/FR-NAS/src/search/search.py", line 64, in <module>
    smac = MultiFidelityFacade(
  File "/home/sukthank/anaconda3/envs/fairnas/lib/python3.9/site-packages/smac/facade/abstract_facade.py", line 186, in __init__
    client = dask.distributed.Client(scheduler_file="/work/dlclarge2/sukthank-ZCP_Competition/FR-NAS/scheduler-dpn-file.json")
  File "/home/sukthank/anaconda3/envs/fairnas/lib/python3.9/site-packages/distributed/client.py", line 942, in __init__
    self.start(timeout=timeout)
  File "/home/sukthank/anaconda3/envs/fairnas/lib/python3.9/site-packages/distributed/client.py", line 1100, in start
    sync(self.loop, self._start, **kwargs)
  File "/home/sukthank/anaconda3/envs/fairnas/lib/python3.9/site-packages/distributed/utils.py", line 385, in sync
    raise exc.with_traceback(tb)
  File "/home/sukthank/anaconda3/envs/fairnas/lib/python3.9/site-packages/distributed/utils.py", line 358, in f
    result = yield future
  File "/home/sukthank/anaconda3/envs/fairnas/lib/python3.9/site-packages/tornado/gen.py", line 762, in run
    value = future.result()
  File "/home/sukthank/anaconda3/envs/fairnas/lib/python3.9/site-packages/distributed/client.py", line 1192, in _start
    await self._ensure_connected(timeout=timeout)
  File "/home/sukthank/anaconda3/envs/fairnas/lib/python3.9/site-packages/distributed/client.py", line 1255, in _ensure_connected
    comm = await connect(
  File "/home/sukthank/anaconda3/envs/fairnas/lib/python3.9/site-packages/distributed/comm/core.py", line 315, in connect
    raise OSError(
OSError: Timed out trying to connect to tcp://10.5.166.216:1796 after 30 s
